Workbook

Sheet Raw Responses
A1: Solara Renewables — Employee Engagement Survey, Q3 FY 2026-27
A2: Survey window: 17-Aug-2026 to 28-Aug-2026 | Platform: Culture Amp (anonymous) | Response scale: 1=Strongly Disagree to 5=Strongly Agree | Q10 = eNPS (0-10, likelihood to recommend) | CONFIDENTIAL - responses anonymized at source
A4: Respondent ID | B4: Department | C4: Tenure Band | D4: Q1 | E4: Q2 | F4: Q3 | G4: Q4 | H4: Q5 | I4: Q6 | J4: Q7 | K4: Q8 | L4: Q9 | M4: Q10 (eNPS 0-10) | N4: Comment (optional) | O4: Composite Avg (Q1-Q9)
A5: RESP-001 | B5: R&D & Engineering | C5: 1-3 years | D5: 4 | E5: 3 | F5: 5 | G5: 5 | H5: 4 | I5: 5 | J5: 3 | K5: 4 | L5: 5 | M5: 1 | N5: Safety briefings on the shop floor are thorough and well run. | O5: =AVERAGE(D5:L5) -> 4.2222222
A6: RESP-002 | B6: Information Technology | C6: <1 year | D6: 5 | E6: 3 | F6: 3 | G6: 2 | H6: 5 | I6: 4 | J6: 5 | K6: 4 | L6: 2 | M6: 7 | N6: Really enjoy the quarterly town halls, keep them going. | O6: =AVERAGE(D6:L6) -> 3.6666667
A7: RESP-003 | B7: Quality Assurance | C7: 3-5 years | D7: 5 | E7: 1 | F7: 4 | G7: 2 | H7: 5 | I7: 1 | J7: 3 | K7: 4 | L7: 4 | M7: 6 | O7: =AVERAGE(D7:L7) -> 3.2222222
A8: RESP-004 | B8: Manufacturing & Production | C8: 1-3 years | D8: 5 | E8: 2 | F8: 3 | G8: 4 | H8: 5 | I8: 4 | J8: 5 | K8: 5 | L8: 5 | M8: 4 | N8: Would like more structured onboarding for contract staff. | O8: =AVERAGE(D8:L8) -> 4.2222222
A9: RESP-005 | B9: Supply Chain & Procurement | C9: 1-3 years | D9: 4 | E9: 4 | F9: 3 | G9: 4 | H9: 3 | I9: 5 | J9: 4 | K9: 4 | L9: 4 | M9: 7 | N9: Plant floor could use better break-room facilities. | O9: =AVERAGE(D9:L9) -> 3.8888889
A10: RESP-006 | B10: R&D & Engineering | C10: 3-5 years | D10: 5 | E10: 4 | F10: 4 | G10: 4 | H10: 4 | I10: 3 | J10: 4 | K10: 4 | L10: 4 | M10: 6 | N10: Appreciate the flexibility around WFH for R&D team. | O10: =AVERAGE(D10:L10) -> 4
A11: RESP-007 | B11: Human Resources & Admin | C11: 3-5 years | D11: 4 | E11: 5 | F11: 5 | G11: 3 | H11: 3 | I11: 5 | J11: 3 | K11: 4 | L11: 3 | M11: 2 | N11: Would like more structured onboarding for contract staff. | O11: =AVERAGE(D11:L11) -> 3.8888889
A12: RESP-008 | B12: Sales & Marketing | C12: 1-3 years | D12: 5 | E12: 5 | F12: 4 | G12: 5 | H12: 4 | I12: 4 | J12: 3 | K12: 5 | L12: 3 | M12: 4 | O12: =AVERAGE(D12:L12) -> 4.2222222
A13: RESP-009 | B13: Information Technology | C13: 3-5 years | D13: 4 | E13: 5 | F13: 2 | G13: 3 | H13: 3 | I13: 4 | J13: 3 | K13: 2 | L13: 4 | M13: 10 | N13: Appreciate the flexibility around WFH for R&D team. | O13: =AVERAGE(D13:L13) -> 3.3333333
A14: RESP-010 | B14: Supply Chain & Procurement | C14: <1 year | D14: 3 | E14: 4 | F14: 5 | G14: 4 | H14: 5 | I14: 5 | J14: 4 | K14: 3 | L14: 4 | M14: 9 | N14: Really enjoy the quarterly town halls, keep them going. | O14: =AVERAGE(D14:L14) -> 4.1111111
A15: RESP-011 | B15: Supply Chain & Procurement | C15: 1-3 years | D15: 4 | E15: 3 | F15: 5 | G15: 1 | H15: 4 | I15: 5 | J15: 1 | K15: 4 | L15: 4 | M15: 10 | N15: Safety briefings on the shop floor are thorough and well run. | O15: =AVERAGE(D15:L15) -> 3.4444444
A16: RESP-012 | B16: Information Technology | C16: 1-3 years | D16: 4 | E16: 5 | F16: 5 | G16: 3 | H16: 2 | I16: 2 | J16: 1 | K16: 4 | L16: 3 | M16: 10 | O16: =AVERAGE(D16:L16) -> 3.2222222
A17: RESP-013 | B17: Finance & Accounts | C17: <1 year | D17: 4 | E17: 4 | F17: 4 | G17: 3 | H17: 3 | I17: 3 | J17: 4 | K17: 4 | L17: 4 | M17: 3 | O17: =AVERAGE(D17:L17) -> 3.6666667
A18: RESP-014 | B18: Manufacturing & Production | C18: 3-5 years | D18: 1 | E18: 4 | F18: 2 | G18: 5 | H18: 3 | I18: 4 | J18: 3 | K18: 4 | L18: 4 | M18: 3 | N18: Canteen food quality at Plant 1 has dropped recently. | O18: =AVERAGE(D18:L18) -> 3.3333333
A19: RESP-015 | B19: R&D & Engineering | C19: 1-3 years | D19: 5 | E19: 3 | F19: 4 | G19: 4 | H19: 5 | I19: 2 | J19: 4 | K19: 4 | L19: 4 | M19: 10 | N19: Compensation review cycle feels slow compared to market. | O19: =AVERAGE(D19:L19) -> 3.8888889
A20: RESP-016 | B20: Finance & Accounts | C20: 3-5 years | D20: 4 | E20: 4 | F20: 2 | G20: 5 | H20: 5 | I20: 4 | J20: 4 | K20: 5 | L20: 3 | M20: 4 | N20: Plant floor could use better break-room facilities. | O20: =AVERAGE(D20:L20) -> 4
A21: RESP-017 | B21: Supply Chain & Procurement | C21: 1-3 years | D21: 5 | E21: 4 | F21: 4 | G21: 4 | H21: 4 | I21: 5 | J21: 2 | K21: 1 | L21: 4 | M21: 3 | N21: Compensation review cycle feels slow compared to market. | O21: =AVERAGE(D21:L21) -> 3.6666667
A22: RESP-018 | B22: Information Technology | C22: 3-5 years | D22: 4 | E22: 3 | F22: 4 | G22: 4 | H22: 4 | I22: 5 | J22: 2 | K22: 4 | L22: 4 | M22: 9 | N22: Manager check-ins have improved a lot this year. | O22: =AVERAGE(D22:L22) -> 3.7777778
A23: RESP-019 | B23: Supply Chain & Procurement | C23: 3-5 years | D23: 5 | E23: 4 | F23: 5 | G23: 4 | H23: 4 | I23: 3 | J23: 5 | K23: 4 | L23: 4 | M23: 10 | O23: =AVERAGE(D23:L23) -> 4.2222222
A24: RESP-020 | B24: Manufacturing & Production | C24: <1 year | D24: 3 | E24: 5 | F24: 4 | G24: 2 | H24: 3 | I24: 4 | J24: 4 | K24: 4 | L24: 4 | M24: 10 | N24: Appreciate the flexibility around WFH for R&D team. | O24: =AVERAGE(D24:L24) -> 3.6666667
A25: RESP-021 | B25: Information Technology | C25: <1 year | D25: 4 | E25: 4 | F25: 4 | G25: 3 | H25: 5 | I25: 4 | J25: 3 | K25: 5 | L25: 3 | M25: 9 | N25: Manager check-ins have improved a lot this year. | O25: =AVERAGE(D25:L25) -> 3.8888889
A26: RESP-022 | B26: Sales & Marketing | C26: 1-3 years | D26: 3 | E26: 4 | F26: 5 | G26: 4 | H26: 4 | I26: 4 | J26: 3 | K26: 3 | L26: 4 | M26: 7 | N26: Manager check-ins have improved a lot this year. | O26: =AVERAGE(D26:L26) -> 3.7777778
A27: RESP-023 | B27: Sales & Marketing | C27: <1 year | D27: 5 | E27: 5 | F27: 4 | G27: 1 | H27: 4 | I27: 2 | J27: 4 | K27: 4 | L27: 3 | M27: 0 | N27: Would like more structured onboarding for contract staff. | O27: =AVERAGE(D27:L27) -> 3.5555556
A28: RESP-024 | B28: R&D & Engineering | C28: <1 year | D28: 4 | E28: 4 | F28: 5 | G28: 4 | H28: 3 | I28: 5 | J28: 5 | K28: 4 | L28: 2 | M28: 6 | N28: Canteen food quality at Plant 1 has dropped recently. | O28: =AVERAGE(D28:L28) -> 4
A29: RESP-025 | B29: Sales & Marketing | C29: <1 year | D29: 5 | E29: 5 | F29: 5 | G29: 5 | H29: 1 | I29: 4 | J29: 2 | K29: 5 | L29: 4 | M29: 9 | N29: Manager check-ins have improved a lot this year. | O29: =AVERAGE(D29:L29) -> 4
A30: RESP-026 | B30: R&D & Engineering | C30: <1 year | D30: 5 | E30: 4 | F30: 4 | G30: 4 | H30: 5 | I30: 4 | J30: 3 | K30: 4 | L30: 3 | M30: 9 | O30: =AVERAGE(D30:L30) -> 4
A31: RESP-027 | B31: Quality Assurance | C31: 3-5 years | D31: 3 | E31: 2 | F31: 5 | G31: 4 | H31: 4 | I31: 3 | J31: 4 | K31: 3 | L31: 5 | M31: 8 | N31: Would like more clarity on the career ladder for engineering roles. | O31: =AVERAGE(D31:L31) -> 3.6666667
A32: RESP-028 | B32: Quality Assurance | C32: <1 year | D32: 4 | E32: 3 | F32: 3 | G32: 3 | H32: 5 | I32: 4 | J32: 4 | K32: 3 | L32: 4 | M32: 9 | N32: Safety briefings on the shop floor are thorough and well run. | O32: =AVERAGE(D32:L32) -> 3.6666667
A33: RESP-029 | B33: R&D & Engineering | C33: <1 year | D33: 4 | E33: 4 | F33: 5 | G33: 4 | H33: 1 | I33: 3 | J33: 2 | K33: 4 | L33: 4 | M33: 9 | N33: Safety briefings on the shop floor are thorough and well run. | O33: =AVERAGE(D33:L33) -> 3.4444444
A34: RESP-030 | B34: Quality Assurance | C34: >5 years | D34: 4 | E34: 5 | F34: 5 | G34: 5 | H34: 1 | I34: 4 | J34: 4 | K34: 4 | L34: 5 | M34: 9 | N34: Appreciate the flexibility around WFH for R&D team. | O34: =AVERAGE(D34:L34) -> 4.1111111
A35: RESP-031 | B35: R&D & Engineering | C35: >5 years | D35: 4 | E35: 5 | F35: 3 | G35: 5 | H35: 4 | I35: 5 | J35: 4 | K35: 5 | L35: 4 | M35: 4 | N35: Canteen food quality at Plant 1 has dropped recently. | O35: =AVERAGE(D35:L35) -> 4.3333333
A36: RESP-032 | B36: R&D & Engineering | C36: 1-3 years | D36: 4 | E36: 5 | F36: 4 | G36: 5 | H36: 5 | I36: 5 | J36: 5 | K36: 5 | L36: 4 | M36: 9 | N36: Manager check-ins have improved a lot this year. | O36: =AVERAGE(D36:L36) -> 4.6666667
A37: RESP-033 | B37: Human Resources & Admin | C37: >5 years | D37: 4 | E37: 3 | F37: 3 | G37: 4 | H37: 4 | I37: 5 | J37: 5 | K37: 4 | L37: 3 | M37: 8 | N37: Canteen food quality at Plant 1 has dropped recently. | O37: =AVERAGE(D37:L37) -> 3.8888889
A38: RESP-034 | B38: Sales & Marketing | C38: 1-3 years | D38: 3 | E38: 4 | F38: 4 | G38: 2 | H38: 5 | I38: 4 | J38: 5 | K38: 4 | L38: 4 | M38: 10 | N38: Canteen food quality at Plant 1 has dropped recently. | O38: =AVERAGE(D38:L38) -> 3.8888889
A39: RESP-035 | B39: R&D & Engineering | C39: 1-3 years | D39: 1 | E39: 4 | F39: 4 | G39: 4 | H39: 5 | I39: 3 | J39: 3 | K39: 4 | L39: 5 | M39: 8 | N39: Would like more clarity on the career ladder for engineering roles. | O39: =AVERAGE(D39:L39) -> 3.6666667
A40: RESP-036 | B40: Manufacturing & Production | C40: 1-3 years | D40: 5 | E40: 4 | F40: 4 | G40: 4 | H40: 4 | I40: 4 | J40: 4 | K40: 5 | L40: 5 | M40: 8 | N40: Compensation review cycle feels slow compared to market. | O40: =AVERAGE(D40:L40) -> 4.3333333
A41: RESP-037 | B41: Supply Chain & Procurement | C41: 3-5 years | D41: 5 | E41: 3 | F41: 5 | G41: 5 | H41: 2 | I41: 4 | J41: 4 | K41: 3 | L41: 5 | M41: 7 | O41: =AVERAGE(D41:L41) -> 4
...

Sheet Summary
A1: Solara Renewables — Engagement Survey Summary, Q3 FY 2026-27
A2: Auto-calculated from Raw Responses tab.
A4: Overall Metrics
A5: Employees invited | B5: 287
A6: Responses received | B6: =COUNTA('Raw Responses'!A5:A46) -> 42
A7: Response rate | B7: =B6/B5 -> 0.14634146
A8: Average engagement score (Q1-Q9, out of 5) | B8: =AVERAGE('Raw Responses'!D5:L46) -> 3.8227513
A9: eNPS (Promoters % - Detractors %, Q10) | B9: =(COUNTIF('Raw Responses'!M5:M46,">=9")-COUNTIF('Raw Responses'!M5:M46,"<=6"))/COUNTA('Raw Responses'!M5:M46) -> 0.14285714
A11: Average Score by Question
A12: Question | B12: Average Score
A13: Q1. I understand how my role contributes to Solara's goals. | B13: =AVERAGE('Raw Responses'!D5:D46) -> 3.952381
A14: Q2. I have the tools and resources I need to do my job well. | B14: =AVERAGE('Raw Responses'!E5:E46) -> 3.8333333
A15: Q3. My manager provides regular, useful feedback. | B15: =AVERAGE('Raw Responses'!F5:F46) -> 4.0238095
A16: Q4. I feel recognized for the work I do. | B16: =AVERAGE('Raw Responses'!G5:G46) -> 3.7380952
A17: Q5. I see clear opportunities to grow my career at Solara. | B17: =AVERAGE('Raw Responses'!H5:H46) -> 3.7142857
A18: Q6. I feel safe raising concerns without fear of negative consequences. | B18: =AVERAGE('Raw Responses'!I5:I46) -> 3.8809524
A19: Q7. Solara supports a healthy work-life balance. | B19: =AVERAGE('Raw Responses'!J5:J46) -> 3.5714286
A20: Q8. I am satisfied with my compensation and benefits. | B20: =AVERAGE('Raw Responses'!K5:K46) -> 3.9285714
A21: Q9. Overall, I am satisfied working at Solara. | B21: =AVERAGE('Raw Responses'!L5:L46) -> 3.7619048
A23: Average Engagement Score by Department
A24: Department | B24: Avg Score (Q1-Q9) | C24: Respondents
A25: Manufacturing & Production | B25: =IFERROR(AVERAGEIF('Raw Responses'!B5:B46,A25,'Raw Responses'!O5:O46),"No responses") -> 3.9111111 | C25: =COUNTIF('Raw Responses'!B5:B46,A25) -> 5
A26: Quality Assurance | B26: =IFERROR(AVERAGEIF('Raw Responses'!B5:B46,A26,'Raw Responses'!O5:O46),"No responses") -> 3.6666667 | C26: =COUNTIF('Raw Responses'!B5:B46,A26) -> 4
A27: R&D & Engineering | B27: =IFERROR(AVERAGEIF('Raw Responses'!B5:B46,A27,'Raw Responses'!O5:O46),"No responses") -> 3.9333333 | C27: =COUNTIF('Raw Responses'!B5:B46,A27) -> 10
A28: Sales & Marketing | B28: =IFERROR(AVERAGEIF('Raw Responses'!B5:B46,A28,'Raw Responses'!O5:O46),"No responses") -> 3.8888889 | C28: =COUNTIF('Raw Responses'!B5:B46,A28) -> 5
A29: Finance & Accounts | B29: =IFERROR(AVERAGEIF('Raw Responses'!B5:B46,A29,'Raw Responses'!O5:O46),"No responses") -> 3.7777778 | C29: =COUNTIF('Raw Responses'!B5:B46,A29) -> 3
A30: Human Resources & Admin | B30: =IFERROR(AVERAGEIF('Raw Responses'!B5:B46,A30,'Raw Responses'!O5:O46),"No responses") -> 3.8148148 | C30: =COUNTIF('Raw Responses'!B5:B46,A30) -> 3
A31: Information Technology | B31: =IFERROR(AVERAGEIF('Raw Responses'!B5:B46,A31,'Raw Responses'!O5:O46),"No responses") -> 3.5777778 | C31: =COUNTIF('Raw Responses'!B5:B46,A31) -> 5
A32: Supply Chain & Procurement | B32: =IFERROR(AVERAGEIF('Raw Responses'!B5:B46,A32,'Raw Responses'!O5:O46),"No responses") -> 3.8412698 | C32: =COUNTIF('Raw Responses'!B5:B46,A32) -> 7
